2021-05-09 14:42:35,300 | [WARNING] | Not Found: /
2021-05-09 14:42:35,533 | [WARNING] | Not Found: /favicon.ico
2021-05-09 15:12:21,447 | [WARNING] | Not Found: /favicon.ico
2021-05-09 15:30:33,976 | [ERROR] | Internal Server Error: /admin/
Traceback (most recent call last):
  File "/home/ubuntu/.local/lib/python3.9/site-packages/django/contrib/sessions/backends/base.py", line 233, in _get_session
    return self._session_cache
AttributeError: 'SessionStore' object has no attribute '_session_cache'

During handling of the above exception, another exception occurred:

Traceback (most recent call last):
  File "/home/ubuntu/.local/lib/python3.9/site-packages/django/db/backends/base/base.py", line 219, in ensure_connection
    self.connect()
  File "/home/ubuntu/.local/lib/python3.9/site-packages/django/utils/asyncio.py", line 26, in inner
    return func(*args, **kwargs)
  File "/home/ubuntu/.local/lib/python3.9/site-packages/django/db/backends/base/base.py", line 200, in connect
    self.connection = self.get_new_connection(conn_params)
  File "/home/ubuntu/.local/lib/python3.9/site-packages/django/utils/asyncio.py", line 26, in inner
    return func(*args, **kwargs)
  File "/home/ubuntu/.local/lib/python3.9/site-packages/django/db/backends/mysql/base.py", line 234, in get_new_connection
    connection = Database.connect(**conn_params)
  File "/home/ubuntu/.local/lib/python3.9/site-packages/MySQLdb/__init__.py", line 130, in Connect
    return Connection(*args, **kwargs)
  File "/home/ubuntu/.local/lib/python3.9/site-packages/MySQLdb/connections.py", line 185, in __init__
    super().__init__(*args, **kwargs2)
MySQLdb._exceptions.OperationalError: (2002, "Can't connect to local MySQL server through socket '/var/run/mysqld/mysqld.sock' (2)")

The above exception was the direct cause of the following exception:

Traceback (most recent call last):
  File "/home/ubuntu/.local/lib/python3.9/site-packages/django/core/handlers/exception.py", line 47, in inner
    response = get_response(request)
  File "/home/ubuntu/.local/lib/python3.9/site-packages/django/core/handlers/base.py", line 181, in _get_response
    response = wrapped_callback(request, *callback_args, **callback_kwargs)
  File "/home/ubuntu/.local/lib/python3.9/site-packages/django/contrib/admin/sites.py", line 250, in wrapper
    return self.admin_view(view, cacheable)(*args, **kwargs)
  File "/home/ubuntu/.local/lib/python3.9/site-packages/django/utils/decorators.py", line 130, in _wrapped_view
    response = view_func(request, *args, **kwargs)
  File "/home/ubuntu/.local/lib/python3.9/site-packages/django/views/decorators/cache.py", line 44, in _wrapped_view_func
    response = view_func(request, *args, **kwargs)
  File "/home/ubuntu/.local/lib/python3.9/site-packages/django/contrib/admin/sites.py", line 221, in inner
    if not self.has_permission(request):
  File "/home/ubuntu/.local/lib/python3.9/site-packages/django/contrib/admin/sites.py", line 195, in has_permission
    return request.user.is_active and request.user.is_staff
  File "/home/ubuntu/.local/lib/python3.9/site-packages/django/utils/functional.py", line 246, in inner
    self._setup()
  File "/home/ubuntu/.local/lib/python3.9/site-packages/django/utils/functional.py", line 382, in _setup
    self._wrapped = self._setupfunc()
  File "/home/ubuntu/.local/lib/python3.9/site-packages/django/contrib/auth/middleware.py", line 23, in <lambda>
    request.user = SimpleLazyObject(lambda: get_user(request))
  File "/home/ubuntu/.local/lib/python3.9/site-packages/django/contrib/auth/middleware.py", line 11, in get_user
    request._cached_user = auth.get_user(request)
  File "/home/ubuntu/.local/lib/python3.9/site-packages/django/contrib/auth/__init__.py", line 177, in get_user
    user_id = _get_user_session_key(request)
  File "/home/ubuntu/.local/lib/python3.9/site-packages/django/contrib/auth/__init__.py", line 60, in _get_user_session_key
    return get_user_model()._meta.pk.to_python(request.session[SESSION_KEY])
  File "/home/ubuntu/.local/lib/python3.9/site-packages/django/contrib/sessions/backends/base.py", line 65, in __getitem__
    return self._session[key]
  File "/home/ubuntu/.local/lib/python3.9/site-packages/django/contrib/sessions/backends/base.py", line 238, in _get_session
    self._session_cache = self.load()
  File "/home/ubuntu/.local/lib/python3.9/site-packages/django/contrib/sessions/backends/db.py", line 43, in load
    s = self._get_session_from_db()
  File "/home/ubuntu/.local/lib/python3.9/site-packages/django/contrib/sessions/backends/db.py", line 32, in _get_session_from_db
    return self.model.objects.get(
  File "/home/ubuntu/.local/lib/python3.9/site-packages/django/db/models/manager.py", line 85, in manager_method
    return getattr(self.get_queryset(), name)(*args, **kwargs)
  File "/home/ubuntu/.local/lib/python3.9/site-packages/django/db/models/query.py", line 431, in get
    num = len(clone)
  File "/home/ubuntu/.local/lib/python3.9/site-packages/django/db/models/query.py", line 262, in __len__
    self._fetch_all()
  File "/home/ubuntu/.local/lib/python3.9/site-packages/django/db/models/query.py", line 1324, in _fetch_all
    self._result_cache = list(self._iterable_class(self))
  File "/home/ubuntu/.local/lib/python3.9/site-packages/django/db/models/query.py", line 51, in __iter__
    results = compiler.execute_sql(chunked_fetch=self.chunked_fetch, chunk_size=self.chunk_size)
  File "/home/ubuntu/.local/lib/python3.9/site-packages/django/db/models/sql/compiler.py", line 1173, in execute_sql
    cursor = self.connection.cursor()
  File "/home/ubuntu/.local/lib/python3.9/site-packages/django/utils/asyncio.py", line 26, in inner
    return func(*args, **kwargs)
  File "/home/ubuntu/.local/lib/python3.9/site-packages/django/db/backends/base/base.py", line 259, in cursor
    return self._cursor()
  File "/home/ubuntu/.local/lib/python3.9/site-packages/django/db/backends/base/base.py", line 235, in _cursor
    self.ensure_connection()
  File "/home/ubuntu/.local/lib/python3.9/site-packages/django/utils/asyncio.py", line 26, in inner
    return func(*args, **kwargs)
  File "/home/ubuntu/.local/lib/python3.9/site-packages/django/db/backends/base/base.py", line 219, in ensure_connection
    self.connect()
  File "/home/ubuntu/.local/lib/python3.9/site-packages/django/db/utils.py", line 90, in __exit__
    raise dj_exc_value.with_traceback(traceback) from exc_value
  File "/home/ubuntu/.local/lib/python3.9/site-packages/django/db/backends/base/base.py", line 219, in ensure_connection
    self.connect()
  File "/home/ubuntu/.local/lib/python3.9/site-packages/django/utils/asyncio.py", line 26, in inner
    return func(*args, **kwargs)
  File "/home/ubuntu/.local/lib/python3.9/site-packages/django/db/backends/base/base.py", line 200, in connect
    self.connection = self.get_new_connection(conn_params)
  File "/home/ubuntu/.local/lib/python3.9/site-packages/django/utils/asyncio.py", line 26, in inner
    return func(*args, **kwargs)
  File "/home/ubuntu/.local/lib/python3.9/site-packages/django/db/backends/mysql/base.py", line 234, in get_new_connection
    connection = Database.connect(**conn_params)
  File "/home/ubuntu/.local/lib/python3.9/site-packages/MySQLdb/__init__.py", line 130, in Connect
    return Connection(*args, **kwargs)
  File "/home/ubuntu/.local/lib/python3.9/site-packages/MySQLdb/connections.py", line 185, in __init__
    super().__init__(*args, **kwargs2)
django.db.utils.OperationalError: (2002, "Can't connect to local MySQL server through socket '/var/run/mysqld/mysqld.sock' (2)")
2021-05-09 15:32:04,279 | [ERROR] | Internal Server Error: /admin/
Traceback (most recent call last):
  File "/home/ubuntu/.local/lib/python3.9/site-packages/django/contrib/sessions/backends/base.py", line 233, in _get_session
    return self._session_cache
AttributeError: 'SessionStore' object has no attribute '_session_cache'

During handling of the above exception, another exception occurred:

Traceback (most recent call last):
  File "/home/ubuntu/.local/lib/python3.9/site-packages/django/db/backends/base/base.py", line 219, in ensure_connection
    self.connect()
  File "/home/ubuntu/.local/lib/python3.9/site-packages/django/utils/asyncio.py", line 26, in inner
    return func(*args, **kwargs)
  File "/home/ubuntu/.local/lib/python3.9/site-packages/django/db/backends/base/base.py", line 200, in connect
    self.connection = self.get_new_connection(conn_params)
  File "/home/ubuntu/.local/lib/python3.9/site-packages/django/utils/asyncio.py", line 26, in inner
    return func(*args, **kwargs)
  File "/home/ubuntu/.local/lib/python3.9/site-packages/django/db/backends/mysql/base.py", line 234, in get_new_connection
    connection = Database.connect(**conn_params)
  File "/home/ubuntu/.local/lib/python3.9/site-packages/MySQLdb/__init__.py", line 130, in Connect
    return Connection(*args, **kwargs)
  File "/home/ubuntu/.local/lib/python3.9/site-packages/MySQLdb/connections.py", line 185, in __init__
    super().__init__(*args, **kwargs2)
MySQLdb._exceptions.OperationalError: (2002, "Can't connect to local MySQL server through socket '/var/run/mysqld/mysqld.sock' (2)")

The above exception was the direct cause of the following exception:

Traceback (most recent call last):
  File "/home/ubuntu/.local/lib/python3.9/site-packages/django/core/handlers/exception.py", line 47, in inner
    response = get_response(request)
  File "/home/ubuntu/.local/lib/python3.9/site-packages/django/core/handlers/base.py", line 181, in _get_response
    response = wrapped_callback(request, *callback_args, **callback_kwargs)
  File "/home/ubuntu/.local/lib/python3.9/site-packages/django/contrib/admin/sites.py", line 250, in wrapper
    return self.admin_view(view, cacheable)(*args, **kwargs)
  File "/home/ubuntu/.local/lib/python3.9/site-packages/django/utils/decorators.py", line 130, in _wrapped_view
    response = view_func(request, *args, **kwargs)
  File "/home/ubuntu/.local/lib/python3.9/site-packages/django/views/decorators/cache.py", line 44, in _wrapped_view_func
    response = view_func(request, *args, **kwargs)
  File "/home/ubuntu/.local/lib/python3.9/site-packages/django/contrib/admin/sites.py", line 221, in inner
    if not self.has_permission(request):
  File "/home/ubuntu/.local/lib/python3.9/site-packages/django/contrib/admin/sites.py", line 195, in has_permission
    return request.user.is_active and request.user.is_staff
  File "/home/ubuntu/.local/lib/python3.9/site-packages/django/utils/functional.py", line 246, in inner
    self._setup()
  File "/home/ubuntu/.local/lib/python3.9/site-packages/django/utils/functional.py", line 382, in _setup
    self._wrapped = self._setupfunc()
  File "/home/ubuntu/.local/lib/python3.9/site-packages/django/contrib/auth/middleware.py", line 23, in <lambda>
    request.user = SimpleLazyObject(lambda: get_user(request))
  File "/home/ubuntu/.local/lib/python3.9/site-packages/django/contrib/auth/middleware.py", line 11, in get_user
    request._cached_user = auth.get_user(request)
  File "/home/ubuntu/.local/lib/python3.9/site-packages/django/contrib/auth/__init__.py", line 177, in get_user
    user_id = _get_user_session_key(request)
  File "/home/ubuntu/.local/lib/python3.9/site-packages/django/contrib/auth/__init__.py", line 60, in _get_user_session_key
    return get_user_model()._meta.pk.to_python(request.session[SESSION_KEY])
  File "/home/ubuntu/.local/lib/python3.9/site-packages/django/contrib/sessions/backends/base.py", line 65, in __getitem__
    return self._session[key]
  File "/home/ubuntu/.local/lib/python3.9/site-packages/django/contrib/sessions/backends/base.py", line 238, in _get_session
    self._session_cache = self.load()
  File "/home/ubuntu/.local/lib/python3.9/site-packages/django/contrib/sessions/backends/db.py", line 43, in load
    s = self._get_session_from_db()
  File "/home/ubuntu/.local/lib/python3.9/site-packages/django/contrib/sessions/backends/db.py", line 32, in _get_session_from_db
    return self.model.objects.get(
  File "/home/ubuntu/.local/lib/python3.9/site-packages/django/db/models/manager.py", line 85, in manager_method
    return getattr(self.get_queryset(), name)(*args, **kwargs)
  File "/home/ubuntu/.local/lib/python3.9/site-packages/django/db/models/query.py", line 431, in get
    num = len(clone)
  File "/home/ubuntu/.local/lib/python3.9/site-packages/django/db/models/query.py", line 262, in __len__
    self._fetch_all()
  File "/home/ubuntu/.local/lib/python3.9/site-packages/django/db/models/query.py", line 1324, in _fetch_all
    self._result_cache = list(self._iterable_class(self))
  File "/home/ubuntu/.local/lib/python3.9/site-packages/django/db/models/query.py", line 51, in __iter__
    results = compiler.execute_sql(chunked_fetch=self.chunked_fetch, chunk_size=self.chunk_size)
  File "/home/ubuntu/.local/lib/python3.9/site-packages/django/db/models/sql/compiler.py", line 1173, in execute_sql
    cursor = self.connection.cursor()
  File "/home/ubuntu/.local/lib/python3.9/site-packages/django/utils/asyncio.py", line 26, in inner
    return func(*args, **kwargs)
  File "/home/ubuntu/.local/lib/python3.9/site-packages/django/db/backends/base/base.py", line 259, in cursor
    return self._cursor()
  File "/home/ubuntu/.local/lib/python3.9/site-packages/django/db/backends/base/base.py", line 235, in _cursor
    self.ensure_connection()
  File "/home/ubuntu/.local/lib/python3.9/site-packages/django/utils/asyncio.py", line 26, in inner
    return func(*args, **kwargs)
  File "/home/ubuntu/.local/lib/python3.9/site-packages/django/db/backends/base/base.py", line 219, in ensure_connection
    self.connect()
  File "/home/ubuntu/.local/lib/python3.9/site-packages/django/db/utils.py", line 90, in __exit__
    raise dj_exc_value.with_traceback(traceback) from exc_value
  File "/home/ubuntu/.local/lib/python3.9/site-packages/django/db/backends/base/base.py", line 219, in ensure_connection
    self.connect()
  File "/home/ubuntu/.local/lib/python3.9/site-packages/django/utils/asyncio.py", line 26, in inner
    return func(*args, **kwargs)
  File "/home/ubuntu/.local/lib/python3.9/site-packages/django/db/backends/base/base.py", line 200, in connect
    self.connection = self.get_new_connection(conn_params)
  File "/home/ubuntu/.local/lib/python3.9/site-packages/django/utils/asyncio.py", line 26, in inner
    return func(*args, **kwargs)
  File "/home/ubuntu/.local/lib/python3.9/site-packages/django/db/backends/mysql/base.py", line 234, in get_new_connection
    connection = Database.connect(**conn_params)
  File "/home/ubuntu/.local/lib/python3.9/site-packages/MySQLdb/__init__.py", line 130, in Connect
    return Connection(*args, **kwargs)
  File "/home/ubuntu/.local/lib/python3.9/site-packages/MySQLdb/connections.py", line 185, in __init__
    super().__init__(*args, **kwargs2)
django.db.utils.OperationalError: (2002, "Can't connect to local MySQL server through socket '/var/run/mysqld/mysqld.sock' (2)")
2021-05-09 15:48:31,998 | [ERROR] | Internal Server Error: /admin/
Traceback (most recent call last):
  File "/home/ubuntu/.local/lib/python3.9/site-packages/django/contrib/sessions/backends/base.py", line 233, in _get_session
    return self._session_cache
AttributeError: 'SessionStore' object has no attribute '_session_cache'

During handling of the above exception, another exception occurred:

Traceback (most recent call last):
  File "/home/ubuntu/.local/lib/python3.9/site-packages/django/db/backends/base/base.py", line 219, in ensure_connection
    self.connect()
  File "/home/ubuntu/.local/lib/python3.9/site-packages/django/utils/asyncio.py", line 26, in inner
    return func(*args, **kwargs)
  File "/home/ubuntu/.local/lib/python3.9/site-packages/django/db/backends/base/base.py", line 200, in connect
    self.connection = self.get_new_connection(conn_params)
  File "/home/ubuntu/.local/lib/python3.9/site-packages/django/utils/asyncio.py", line 26, in inner
    return func(*args, **kwargs)
  File "/home/ubuntu/.local/lib/python3.9/site-packages/django/db/backends/mysql/base.py", line 234, in get_new_connection
    connection = Database.connect(**conn_params)
  File "/home/ubuntu/.local/lib/python3.9/site-packages/MySQLdb/__init__.py", line 130, in Connect
    return Connection(*args, **kwargs)
  File "/home/ubuntu/.local/lib/python3.9/site-packages/MySQLdb/connections.py", line 185, in __init__
    super().__init__(*args, **kwargs2)
MySQLdb._exceptions.OperationalError: (2002, "Can't connect to local MySQL server through socket '/var/run/mysqld/mysqld.sock' (2)")

The above exception was the direct cause of the following exception:

Traceback (most recent call last):
  File "/home/ubuntu/.local/lib/python3.9/site-packages/django/core/handlers/exception.py", line 47, in inner
    response = get_response(request)
  File "/home/ubuntu/.local/lib/python3.9/site-packages/django/core/handlers/base.py", line 181, in _get_response
    response = wrapped_callback(request, *callback_args, **callback_kwargs)
  File "/home/ubuntu/.local/lib/python3.9/site-packages/django/contrib/admin/sites.py", line 250, in wrapper
    return self.admin_view(view, cacheable)(*args, **kwargs)
  File "/home/ubuntu/.local/lib/python3.9/site-packages/django/utils/decorators.py", line 130, in _wrapped_view
    response = view_func(request, *args, **kwargs)
  File "/home/ubuntu/.local/lib/python3.9/site-packages/django/views/decorators/cache.py", line 44, in _wrapped_view_func
    response = view_func(request, *args, **kwargs)
  File "/home/ubuntu/.local/lib/python3.9/site-packages/django/contrib/admin/sites.py", line 221, in inner
    if not self.has_permission(request):
  File "/home/ubuntu/.local/lib/python3.9/site-packages/django/contrib/admin/sites.py", line 195, in has_permission
    return request.user.is_active and request.user.is_staff
  File "/home/ubuntu/.local/lib/python3.9/site-packages/django/utils/functional.py", line 246, in inner
    self._setup()
  File "/home/ubuntu/.local/lib/python3.9/site-packages/django/utils/functional.py", line 382, in _setup
    self._wrapped = self._setupfunc()
  File "/home/ubuntu/.local/lib/python3.9/site-packages/django/contrib/auth/middleware.py", line 23, in <lambda>
    request.user = SimpleLazyObject(lambda: get_user(request))
  File "/home/ubuntu/.local/lib/python3.9/site-packages/django/contrib/auth/middleware.py", line 11, in get_user
    request._cached_user = auth.get_user(request)
  File "/home/ubuntu/.local/lib/python3.9/site-packages/django/contrib/auth/__init__.py", line 177, in get_user
    user_id = _get_user_session_key(request)
  File "/home/ubuntu/.local/lib/python3.9/site-packages/django/contrib/auth/__init__.py", line 60, in _get_user_session_key
    return get_user_model()._meta.pk.to_python(request.session[SESSION_KEY])
  File "/home/ubuntu/.local/lib/python3.9/site-packages/django/contrib/sessions/backends/base.py", line 65, in __getitem__
    return self._session[key]
  File "/home/ubuntu/.local/lib/python3.9/site-packages/django/contrib/sessions/backends/base.py", line 238, in _get_session
    self._session_cache = self.load()
  File "/home/ubuntu/.local/lib/python3.9/site-packages/django/contrib/sessions/backends/db.py", line 43, in load
    s = self._get_session_from_db()
  File "/home/ubuntu/.local/lib/python3.9/site-packages/django/contrib/sessions/backends/db.py", line 32, in _get_session_from_db
    return self.model.objects.get(
  File "/home/ubuntu/.local/lib/python3.9/site-packages/django/db/models/manager.py", line 85, in manager_method
    return getattr(self.get_queryset(), name)(*args, **kwargs)
  File "/home/ubuntu/.local/lib/python3.9/site-packages/django/db/models/query.py", line 431, in get
    num = len(clone)
  File "/home/ubuntu/.local/lib/python3.9/site-packages/django/db/models/query.py", line 262, in __len__
    self._fetch_all()
  File "/home/ubuntu/.local/lib/python3.9/site-packages/django/db/models/query.py", line 1324, in _fetch_all
    self._result_cache = list(self._iterable_class(self))
  File "/home/ubuntu/.local/lib/python3.9/site-packages/django/db/models/query.py", line 51, in __iter__
    results = compiler.execute_sql(chunked_fetch=self.chunked_fetch, chunk_size=self.chunk_size)
  File "/home/ubuntu/.local/lib/python3.9/site-packages/django/db/models/sql/compiler.py", line 1173, in execute_sql
    cursor = self.connection.cursor()
  File "/home/ubuntu/.local/lib/python3.9/site-packages/django/utils/asyncio.py", line 26, in inner
    return func(*args, **kwargs)
  File "/home/ubuntu/.local/lib/python3.9/site-packages/django/db/backends/base/base.py", line 259, in cursor
    return self._cursor()
  File "/home/ubuntu/.local/lib/python3.9/site-packages/django/db/backends/base/base.py", line 235, in _cursor
    self.ensure_connection()
  File "/home/ubuntu/.local/lib/python3.9/site-packages/django/utils/asyncio.py", line 26, in inner
    return func(*args, **kwargs)
  File "/home/ubuntu/.local/lib/python3.9/site-packages/django/db/backends/base/base.py", line 219, in ensure_connection
    self.connect()
  File "/home/ubuntu/.local/lib/python3.9/site-packages/django/db/utils.py", line 90, in __exit__
    raise dj_exc_value.with_traceback(traceback) from exc_value
  File "/home/ubuntu/.local/lib/python3.9/site-packages/django/db/backends/base/base.py", line 219, in ensure_connection
    self.connect()
  File "/home/ubuntu/.local/lib/python3.9/site-packages/django/utils/asyncio.py", line 26, in inner
    return func(*args, **kwargs)
  File "/home/ubuntu/.local/lib/python3.9/site-packages/django/db/backends/base/base.py", line 200, in connect
    self.connection = self.get_new_connection(conn_params)
  File "/home/ubuntu/.local/lib/python3.9/site-packages/django/utils/asyncio.py", line 26, in inner
    return func(*args, **kwargs)
  File "/home/ubuntu/.local/lib/python3.9/site-packages/django/db/backends/mysql/base.py", line 234, in get_new_connection
    connection = Database.connect(**conn_params)
  File "/home/ubuntu/.local/lib/python3.9/site-packages/MySQLdb/__init__.py", line 130, in Connect
    return Connection(*args, **kwargs)
  File "/home/ubuntu/.local/lib/python3.9/site-packages/MySQLdb/connections.py", line 185, in __init__
    super().__init__(*args, **kwargs2)
django.db.utils.OperationalError: (2002, "Can't connect to local MySQL server through socket '/var/run/mysqld/mysqld.sock' (2)")
2021-05-09 15:55:55,629 | [ERROR] | Internal Server Error: /admin/
Traceback (most recent call last):
  File "/home/ubuntu/.local/lib/python3.9/site-packages/django/contrib/sessions/backends/base.py", line 233, in _get_session
    return self._session_cache
AttributeError: 'SessionStore' object has no attribute '_session_cache'

During handling of the above exception, another exception occurred:

Traceback (most recent call last):
  File "/home/ubuntu/.local/lib/python3.9/site-packages/django/db/backends/base/base.py", line 219, in ensure_connection
    self.connect()
  File "/home/ubuntu/.local/lib/python3.9/site-packages/django/utils/asyncio.py", line 26, in inner
    return func(*args, **kwargs)
  File "/home/ubuntu/.local/lib/python3.9/site-packages/django/db/backends/base/base.py", line 200, in connect
    self.connection = self.get_new_connection(conn_params)
  File "/home/ubuntu/.local/lib/python3.9/site-packages/django/utils/asyncio.py", line 26, in inner
    return func(*args, **kwargs)
  File "/home/ubuntu/.local/lib/python3.9/site-packages/django/db/backends/mysql/base.py", line 234, in get_new_connection
    connection = Database.connect(**conn_params)
  File "/home/ubuntu/.local/lib/python3.9/site-packages/MySQLdb/__init__.py", line 130, in Connect
    return Connection(*args, **kwargs)
  File "/home/ubuntu/.local/lib/python3.9/site-packages/MySQLdb/connections.py", line 185, in __init__
    super().__init__(*args, **kwargs2)
MySQLdb._exceptions.OperationalError: (2002, "Can't connect to local MySQL server through socket '/var/run/mysqld/mysqld.sock' (2)")

The above exception was the direct cause of the following exception:

Traceback (most recent call last):
  File "/home/ubuntu/.local/lib/python3.9/site-packages/django/core/handlers/exception.py", line 47, in inner
    response = get_response(request)
  File "/home/ubuntu/.local/lib/python3.9/site-packages/django/core/handlers/base.py", line 181, in _get_response
    response = wrapped_callback(request, *callback_args, **callback_kwargs)
  File "/home/ubuntu/.local/lib/python3.9/site-packages/django/contrib/admin/sites.py", line 250, in wrapper
    return self.admin_view(view, cacheable)(*args, **kwargs)
  File "/home/ubuntu/.local/lib/python3.9/site-packages/django/utils/decorators.py", line 130, in _wrapped_view
    response = view_func(request, *args, **kwargs)
  File "/home/ubuntu/.local/lib/python3.9/site-packages/django/views/decorators/cache.py", line 44, in _wrapped_view_func
    response = view_func(request, *args, **kwargs)
  File "/home/ubuntu/.local/lib/python3.9/site-packages/django/contrib/admin/sites.py", line 221, in inner
    if not self.has_permission(request):
  File "/home/ubuntu/.local/lib/python3.9/site-packages/django/contrib/admin/sites.py", line 195, in has_permission
    return request.user.is_active and request.user.is_staff
  File "/home/ubuntu/.local/lib/python3.9/site-packages/django/utils/functional.py", line 246, in inner
    self._setup()
  File "/home/ubuntu/.local/lib/python3.9/site-packages/django/utils/functional.py", line 382, in _setup
    self._wrapped = self._setupfunc()
  File "/home/ubuntu/.local/lib/python3.9/site-packages/django/contrib/auth/middleware.py", line 23, in <lambda>
    request.user = SimpleLazyObject(lambda: get_user(request))
  File "/home/ubuntu/.local/lib/python3.9/site-packages/django/contrib/auth/middleware.py", line 11, in get_user
    request._cached_user = auth.get_user(request)
  File "/home/ubuntu/.local/lib/python3.9/site-packages/django/contrib/auth/__init__.py", line 177, in get_user
    user_id = _get_user_session_key(request)
  File "/home/ubuntu/.local/lib/python3.9/site-packages/django/contrib/auth/__init__.py", line 60, in _get_user_session_key
    return get_user_model()._meta.pk.to_python(request.session[SESSION_KEY])
  File "/home/ubuntu/.local/lib/python3.9/site-packages/django/contrib/sessions/backends/base.py", line 65, in __getitem__
    return self._session[key]
  File "/home/ubuntu/.local/lib/python3.9/site-packages/django/contrib/sessions/backends/base.py", line 238, in _get_session
    self._session_cache = self.load()
  File "/home/ubuntu/.local/lib/python3.9/site-packages/django/contrib/sessions/backends/db.py", line 43, in load
    s = self._get_session_from_db()
  File "/home/ubuntu/.local/lib/python3.9/site-packages/django/contrib/sessions/backends/db.py", line 32, in _get_session_from_db
    return self.model.objects.get(
  File "/home/ubuntu/.local/lib/python3.9/site-packages/django/db/models/manager.py", line 85, in manager_method
    return getattr(self.get_queryset(), name)(*args, **kwargs)
  File "/home/ubuntu/.local/lib/python3.9/site-packages/django/db/models/query.py", line 431, in get
    num = len(clone)
  File "/home/ubuntu/.local/lib/python3.9/site-packages/django/db/models/query.py", line 262, in __len__
    self._fetch_all()
  File "/home/ubuntu/.local/lib/python3.9/site-packages/django/db/models/query.py", line 1324, in _fetch_all
    self._result_cache = list(self._iterable_class(self))
  File "/home/ubuntu/.local/lib/python3.9/site-packages/django/db/models/query.py", line 51, in __iter__
    results = compiler.execute_sql(chunked_fetch=self.chunked_fetch, chunk_size=self.chunk_size)
  File "/home/ubuntu/.local/lib/python3.9/site-packages/django/db/models/sql/compiler.py", line 1173, in execute_sql
    cursor = self.connection.cursor()
  File "/home/ubuntu/.local/lib/python3.9/site-packages/django/utils/asyncio.py", line 26, in inner
    return func(*args, **kwargs)
  File "/home/ubuntu/.local/lib/python3.9/site-packages/django/db/backends/base/base.py", line 259, in cursor
    return self._cursor()
  File "/home/ubuntu/.local/lib/python3.9/site-packages/django/db/backends/base/base.py", line 235, in _cursor
    self.ensure_connection()
  File "/home/ubuntu/.local/lib/python3.9/site-packages/django/utils/asyncio.py", line 26, in inner
    return func(*args, **kwargs)
  File "/home/ubuntu/.local/lib/python3.9/site-packages/django/db/backends/base/base.py", line 219, in ensure_connection
    self.connect()
  File "/home/ubuntu/.local/lib/python3.9/site-packages/django/db/utils.py", line 90, in __exit__
    raise dj_exc_value.with_traceback(traceback) from exc_value
  File "/home/ubuntu/.local/lib/python3.9/site-packages/django/db/backends/base/base.py", line 219, in ensure_connection
    self.connect()
  File "/home/ubuntu/.local/lib/python3.9/site-packages/django/utils/asyncio.py", line 26, in inner
    return func(*args, **kwargs)
  File "/home/ubuntu/.local/lib/python3.9/site-packages/django/db/backends/base/base.py", line 200, in connect
    self.connection = self.get_new_connection(conn_params)
  File "/home/ubuntu/.local/lib/python3.9/site-packages/django/utils/asyncio.py", line 26, in inner
    return func(*args, **kwargs)
  File "/home/ubuntu/.local/lib/python3.9/site-packages/django/db/backends/mysql/base.py", line 234, in get_new_connection
    connection = Database.connect(**conn_params)
  File "/home/ubuntu/.local/lib/python3.9/site-packages/MySQLdb/__init__.py", line 130, in Connect
    return Connection(*args, **kwargs)
  File "/home/ubuntu/.local/lib/python3.9/site-packages/MySQLdb/connections.py", line 185, in __init__
    super().__init__(*args, **kwargs2)
django.db.utils.OperationalError: (2002, "Can't connect to local MySQL server through socket '/var/run/mysqld/mysqld.sock' (2)")
2021-05-09 15:55:55,643 | [ERROR] | Internal Server Error: /admin/
Traceback (most recent call last):
  File "/home/ubuntu/.local/lib/python3.9/site-packages/django/contrib/sessions/backends/base.py", line 233, in _get_session
    return self._session_cache
AttributeError: 'SessionStore' object has no attribute '_session_cache'

During handling of the above exception, another exception occurred:

Traceback (most recent call last):
  File "/home/ubuntu/.local/lib/python3.9/site-packages/django/db/backends/base/base.py", line 219, in ensure_connection
    self.connect()
  File "/home/ubuntu/.local/lib/python3.9/site-packages/django/utils/asyncio.py", line 26, in inner
    return func(*args, **kwargs)
  File "/home/ubuntu/.local/lib/python3.9/site-packages/django/db/backends/base/base.py", line 200, in connect
    self.connection = self.get_new_connection(conn_params)
  File "/home/ubuntu/.local/lib/python3.9/site-packages/django/utils/asyncio.py", line 26, in inner
    return func(*args, **kwargs)
  File "/home/ubuntu/.local/lib/python3.9/site-packages/django/db/backends/mysql/base.py", line 234, in get_new_connection
    connection = Database.connect(**conn_params)
  File "/home/ubuntu/.local/lib/python3.9/site-packages/MySQLdb/__init__.py", line 130, in Connect
    return Connection(*args, **kwargs)
  File "/home/ubuntu/.local/lib/python3.9/site-packages/MySQLdb/connections.py", line 185, in __init__
    super().__init__(*args, **kwargs2)
MySQLdb._exceptions.OperationalError: (2002, "Can't connect to local MySQL server through socket '/var/run/mysqld/mysqld.sock' (2)")

The above exception was the direct cause of the following exception:

Traceback (most recent call last):
  File "/home/ubuntu/.local/lib/python3.9/site-packages/django/core/handlers/exception.py", line 47, in inner
    response = get_response(request)
  File "/home/ubuntu/.local/lib/python3.9/site-packages/django/core/handlers/base.py", line 181, in _get_response
    response = wrapped_callback(request, *callback_args, **callback_kwargs)
  File "/home/ubuntu/.local/lib/python3.9/site-packages/django/contrib/admin/sites.py", line 250, in wrapper
    return self.admin_view(view, cacheable)(*args, **kwargs)
  File "/home/ubuntu/.local/lib/python3.9/site-packages/django/utils/decorators.py", line 130, in _wrapped_view
    response = view_func(request, *args, **kwargs)
  File "/home/ubuntu/.local/lib/python3.9/site-packages/django/views/decorators/cache.py", line 44, in _wrapped_view_func
    response = view_func(request, *args, **kwargs)
  File "/home/ubuntu/.local/lib/python3.9/site-packages/django/contrib/admin/sites.py", line 221, in inner
    if not self.has_permission(request):
  File "/home/ubuntu/.local/lib/python3.9/site-packages/django/contrib/admin/sites.py", line 195, in has_permission
    return request.user.is_active and request.user.is_staff
  File "/home/ubuntu/.local/lib/python3.9/site-packages/django/utils/functional.py", line 246, in inner
    self._setup()
  File "/home/ubuntu/.local/lib/python3.9/site-packages/django/utils/functional.py", line 382, in _setup
    self._wrapped = self._setupfunc()
  File "/home/ubuntu/.local/lib/python3.9/site-packages/django/contrib/auth/middleware.py", line 23, in <lambda>
    request.user = SimpleLazyObject(lambda: get_user(request))
  File "/home/ubuntu/.local/lib/python3.9/site-packages/django/contrib/auth/middleware.py", line 11, in get_user
    request._cached_user = auth.get_user(request)
  File "/home/ubuntu/.local/lib/python3.9/site-packages/django/contrib/auth/__init__.py", line 177, in get_user
    user_id = _get_user_session_key(request)
  File "/home/ubuntu/.local/lib/python3.9/site-packages/django/contrib/auth/__init__.py", line 60, in _get_user_session_key
    return get_user_model()._meta.pk.to_python(request.session[SESSION_KEY])
  File "/home/ubuntu/.local/lib/python3.9/site-packages/django/contrib/sessions/backends/base.py", line 65, in __getitem__
    return self._session[key]
  File "/home/ubuntu/.local/lib/python3.9/site-packages/django/contrib/sessions/backends/base.py", line 238, in _get_session
    self._session_cache = self.load()
  File "/home/ubuntu/.local/lib/python3.9/site-packages/django/contrib/sessions/backends/db.py", line 43, in load
    s = self._get_session_from_db()
  File "/home/ubuntu/.local/lib/python3.9/site-packages/django/contrib/sessions/backends/db.py", line 32, in _get_session_from_db
    return self.model.objects.get(
  File "/home/ubuntu/.local/lib/python3.9/site-packages/django/db/models/manager.py", line 85, in manager_method
    return getattr(self.get_queryset(), name)(*args, **kwargs)
  File "/home/ubuntu/.local/lib/python3.9/site-packages/django/db/models/query.py", line 431, in get
    num = len(clone)
  File "/home/ubuntu/.local/lib/python3.9/site-packages/django/db/models/query.py", line 262, in __len__
    self._fetch_all()
  File "/home/ubuntu/.local/lib/python3.9/site-packages/django/db/models/query.py", line 1324, in _fetch_all
    self._result_cache = list(self._iterable_class(self))
  File "/home/ubuntu/.local/lib/python3.9/site-packages/django/db/models/query.py", line 51, in __iter__
    results = compiler.execute_sql(chunked_fetch=self.chunked_fetch, chunk_size=self.chunk_size)
  File "/home/ubuntu/.local/lib/python3.9/site-packages/django/db/models/sql/compiler.py", line 1173, in execute_sql
    cursor = self.connection.cursor()
  File "/home/ubuntu/.local/lib/python3.9/site-packages/django/utils/asyncio.py", line 26, in inner
    return func(*args, **kwargs)
  File "/home/ubuntu/.local/lib/python3.9/site-packages/django/db/backends/base/base.py", line 259, in cursor
    return self._cursor()
  File "/home/ubuntu/.local/lib/python3.9/site-packages/django/db/backends/base/base.py", line 235, in _cursor
    self.ensure_connection()
  File "/home/ubuntu/.local/lib/python3.9/site-packages/django/utils/asyncio.py", line 26, in inner
    return func(*args, **kwargs)
  File "/home/ubuntu/.local/lib/python3.9/site-packages/django/db/backends/base/base.py", line 219, in ensure_connection
    self.connect()
  File "/home/ubuntu/.local/lib/python3.9/site-packages/django/db/utils.py", line 90, in __exit__
    raise dj_exc_value.with_traceback(traceback) from exc_value
  File "/home/ubuntu/.local/lib/python3.9/site-packages/django/db/backends/base/base.py", line 219, in ensure_connection
    self.connect()
  File "/home/ubuntu/.local/lib/python3.9/site-packages/django/utils/asyncio.py", line 26, in inner
    return func(*args, **kwargs)
  File "/home/ubuntu/.local/lib/python3.9/site-packages/django/db/backends/base/base.py", line 200, in connect
    self.connection = self.get_new_connection(conn_params)
  File "/home/ubuntu/.local/lib/python3.9/site-packages/django/utils/asyncio.py", line 26, in inner
    return func(*args, **kwargs)
  File "/home/ubuntu/.local/lib/python3.9/site-packages/django/db/backends/mysql/base.py", line 234, in get_new_connection
    connection = Database.connect(**conn_params)
  File "/home/ubuntu/.local/lib/python3.9/site-packages/MySQLdb/__init__.py", line 130, in Connect
    return Connection(*args, **kwargs)
  File "/home/ubuntu/.local/lib/python3.9/site-packages/MySQLdb/connections.py", line 185, in __init__
    super().__init__(*args, **kwargs2)
django.db.utils.OperationalError: (2002, "Can't connect to local MySQL server through socket '/var/run/mysqld/mysqld.sock' (2)")
2021-05-09 15:58:44,416 | [ERROR] | Internal Server Error: /admin/
Traceback (most recent call last):
  File "/home/ubuntu/.local/lib/python3.9/site-packages/django/contrib/sessions/backends/base.py", line 233, in _get_session
    return self._session_cache
AttributeError: 'SessionStore' object has no attribute '_session_cache'

During handling of the above exception, another exception occurred:

Traceback (most recent call last):
  File "/home/ubuntu/.local/lib/python3.9/site-packages/django/db/backends/base/base.py", line 219, in ensure_connection
    self.connect()
  File "/home/ubuntu/.local/lib/python3.9/site-packages/django/utils/asyncio.py", line 26, in inner
    return func(*args, **kwargs)
  File "/home/ubuntu/.local/lib/python3.9/site-packages/django/db/backends/base/base.py", line 200, in connect
    self.connection = self.get_new_connection(conn_params)
  File "/home/ubuntu/.local/lib/python3.9/site-packages/django/utils/asyncio.py", line 26, in inner
    return func(*args, **kwargs)
  File "/home/ubuntu/.local/lib/python3.9/site-packages/django/db/backends/mysql/base.py", line 234, in get_new_connection
    connection = Database.connect(**conn_params)
  File "/home/ubuntu/.local/lib/python3.9/site-packages/MySQLdb/__init__.py", line 130, in Connect
    return Connection(*args, **kwargs)
  File "/home/ubuntu/.local/lib/python3.9/site-packages/MySQLdb/connections.py", line 185, in __init__
    super().__init__(*args, **kwargs2)
MySQLdb._exceptions.OperationalError: (2002, "Can't connect to local MySQL server through socket '/var/run/mysqld/mysqld.sock' (2)")

The above exception was the direct cause of the following exception:

Traceback (most recent call last):
  File "/home/ubuntu/.local/lib/python3.9/site-packages/django/core/handlers/exception.py", line 47, in inner
    response = get_response(request)
  File "/home/ubuntu/.local/lib/python3.9/site-packages/django/core/handlers/base.py", line 181, in _get_response
    response = wrapped_callback(request, *callback_args, **callback_kwargs)
  File "/home/ubuntu/.local/lib/python3.9/site-packages/django/contrib/admin/sites.py", line 250, in wrapper
    return self.admin_view(view, cacheable)(*args, **kwargs)
  File "/home/ubuntu/.local/lib/python3.9/site-packages/django/utils/decorators.py", line 130, in _wrapped_view
    response = view_func(request, *args, **kwargs)
  File "/home/ubuntu/.local/lib/python3.9/site-packages/django/views/decorators/cache.py", line 44, in _wrapped_view_func
    response = view_func(request, *args, **kwargs)
  File "/home/ubuntu/.local/lib/python3.9/site-packages/django/contrib/admin/sites.py", line 221, in inner
    if not self.has_permission(request):
  File "/home/ubuntu/.local/lib/python3.9/site-packages/django/contrib/admin/sites.py", line 195, in has_permission
    return request.user.is_active and request.user.is_staff
  File "/home/ubuntu/.local/lib/python3.9/site-packages/django/utils/functional.py", line 246, in inner
    self._setup()
  File "/home/ubuntu/.local/lib/python3.9/site-packages/django/utils/functional.py", line 382, in _setup
    self._wrapped = self._setupfunc()
  File "/home/ubuntu/.local/lib/python3.9/site-packages/django/contrib/auth/middleware.py", line 23, in <lambda>
    request.user = SimpleLazyObject(lambda: get_user(request))
  File "/home/ubuntu/.local/lib/python3.9/site-packages/django/contrib/auth/middleware.py", line 11, in get_user
    request._cached_user = auth.get_user(request)
  File "/home/ubuntu/.local/lib/python3.9/site-packages/django/contrib/auth/__init__.py", line 177, in get_user
    user_id = _get_user_session_key(request)
  File "/home/ubuntu/.local/lib/python3.9/site-packages/django/contrib/auth/__init__.py", line 60, in _get_user_session_key
    return get_user_model()._meta.pk.to_python(request.session[SESSION_KEY])
  File "/home/ubuntu/.local/lib/python3.9/site-packages/django/contrib/sessions/backends/base.py", line 65, in __getitem__
    return self._session[key]
  File "/home/ubuntu/.local/lib/python3.9/site-packages/django/contrib/sessions/backends/base.py", line 238, in _get_session
    self._session_cache = self.load()
  File "/home/ubuntu/.local/lib/python3.9/site-packages/django/contrib/sessions/backends/db.py", line 43, in load
    s = self._get_session_from_db()
  File "/home/ubuntu/.local/lib/python3.9/site-packages/django/contrib/sessions/backends/db.py", line 32, in _get_session_from_db
    return self.model.objects.get(
  File "/home/ubuntu/.local/lib/python3.9/site-packages/django/db/models/manager.py", line 85, in manager_method
    return getattr(self.get_queryset(), name)(*args, **kwargs)
  File "/home/ubuntu/.local/lib/python3.9/site-packages/django/db/models/query.py", line 431, in get
    num = len(clone)
  File "/home/ubuntu/.local/lib/python3.9/site-packages/django/db/models/query.py", line 262, in __len__
    self._fetch_all()
  File "/home/ubuntu/.local/lib/python3.9/site-packages/django/db/models/query.py", line 1324, in _fetch_all
    self._result_cache = list(self._iterable_class(self))
  File "/home/ubuntu/.local/lib/python3.9/site-packages/django/db/models/query.py", line 51, in __iter__
    results = compiler.execute_sql(chunked_fetch=self.chunked_fetch, chunk_size=self.chunk_size)
  File "/home/ubuntu/.local/lib/python3.9/site-packages/django/db/models/sql/compiler.py", line 1173, in execute_sql
    cursor = self.connection.cursor()
  File "/home/ubuntu/.local/lib/python3.9/site-packages/django/utils/asyncio.py", line 26, in inner
    return func(*args, **kwargs)
  File "/home/ubuntu/.local/lib/python3.9/site-packages/django/db/backends/base/base.py", line 259, in cursor
    return self._cursor()
  File "/home/ubuntu/.local/lib/python3.9/site-packages/django/db/backends/base/base.py", line 235, in _cursor
    self.ensure_connection()
  File "/home/ubuntu/.local/lib/python3.9/site-packages/django/utils/asyncio.py", line 26, in inner
    return func(*args, **kwargs)
  File "/home/ubuntu/.local/lib/python3.9/site-packages/django/db/backends/base/base.py", line 219, in ensure_connection
    self.connect()
  File "/home/ubuntu/.local/lib/python3.9/site-packages/django/db/utils.py", line 90, in __exit__
    raise dj_exc_value.with_traceback(traceback) from exc_value
  File "/home/ubuntu/.local/lib/python3.9/site-packages/django/db/backends/base/base.py", line 219, in ensure_connection
    self.connect()
  File "/home/ubuntu/.local/lib/python3.9/site-packages/django/utils/asyncio.py", line 26, in inner
    return func(*args, **kwargs)
  File "/home/ubuntu/.local/lib/python3.9/site-packages/django/db/backends/base/base.py", line 200, in connect
    self.connection = self.get_new_connection(conn_params)
  File "/home/ubuntu/.local/lib/python3.9/site-packages/django/utils/asyncio.py", line 26, in inner
    return func(*args, **kwargs)
  File "/home/ubuntu/.local/lib/python3.9/site-packages/django/db/backends/mysql/base.py", line 234, in get_new_connection
    connection = Database.connect(**conn_params)
  File "/home/ubuntu/.local/lib/python3.9/site-packages/MySQLdb/__init__.py", line 130, in Connect
    return Connection(*args, **kwargs)
  File "/home/ubuntu/.local/lib/python3.9/site-packages/MySQLdb/connections.py", line 185, in __init__
    super().__init__(*args, **kwargs2)
django.db.utils.OperationalError: (2002, "Can't connect to local MySQL server through socket '/var/run/mysqld/mysqld.sock' (2)")
2021-05-09 15:58:46,151 | [ERROR] | Internal Server Error: /admin/
Traceback (most recent call last):
  File "/home/ubuntu/.local/lib/python3.9/site-packages/django/contrib/sessions/backends/base.py", line 233, in _get_session
    return self._session_cache
AttributeError: 'SessionStore' object has no attribute '_session_cache'

During handling of the above exception, another exception occurred:

Traceback (most recent call last):
  File "/home/ubuntu/.local/lib/python3.9/site-packages/django/db/backends/base/base.py", line 219, in ensure_connection
    self.connect()
  File "/home/ubuntu/.local/lib/python3.9/site-packages/django/utils/asyncio.py", line 26, in inner
    return func(*args, **kwargs)
  File "/home/ubuntu/.local/lib/python3.9/site-packages/django/db/backends/base/base.py", line 200, in connect
    self.connection = self.get_new_connection(conn_params)
  File "/home/ubuntu/.local/lib/python3.9/site-packages/django/utils/asyncio.py", line 26, in inner
    return func(*args, **kwargs)
  File "/home/ubuntu/.local/lib/python3.9/site-packages/django/db/backends/mysql/base.py", line 234, in get_new_connection
    connection = Database.connect(**conn_params)
  File "/home/ubuntu/.local/lib/python3.9/site-packages/MySQLdb/__init__.py", line 130, in Connect
    return Connection(*args, **kwargs)
  File "/home/ubuntu/.local/lib/python3.9/site-packages/MySQLdb/connections.py", line 185, in __init__
    super().__init__(*args, **kwargs2)
MySQLdb._exceptions.OperationalError: (2002, "Can't connect to local MySQL server through socket '/var/run/mysqld/mysqld.sock' (2)")

The above exception was the direct cause of the following exception:

Traceback (most recent call last):
  File "/home/ubuntu/.local/lib/python3.9/site-packages/django/core/handlers/exception.py", line 47, in inner
    response = get_response(request)
  File "/home/ubuntu/.local/lib/python3.9/site-packages/django/core/handlers/base.py", line 181, in _get_response
    response = wrapped_callback(request, *callback_args, **callback_kwargs)
  File "/home/ubuntu/.local/lib/python3.9/site-packages/django/contrib/admin/sites.py", line 250, in wrapper
    return self.admin_view(view, cacheable)(*args, **kwargs)
  File "/home/ubuntu/.local/lib/python3.9/site-packages/django/utils/decorators.py", line 130, in _wrapped_view
    response = view_func(request, *args, **kwargs)
  File "/home/ubuntu/.local/lib/python3.9/site-packages/django/views/decorators/cache.py", line 44, in _wrapped_view_func
    response = view_func(request, *args, **kwargs)
  File "/home/ubuntu/.local/lib/python3.9/site-packages/django/contrib/admin/sites.py", line 221, in inner
    if not self.has_permission(request):
  File "/home/ubuntu/.local/lib/python3.9/site-packages/django/contrib/admin/sites.py", line 195, in has_permission
    return request.user.is_active and request.user.is_staff
  File "/home/ubuntu/.local/lib/python3.9/site-packages/django/utils/functional.py", line 246, in inner
    self._setup()
  File "/home/ubuntu/.local/lib/python3.9/site-packages/django/utils/functional.py", line 382, in _setup
    self._wrapped = self._setupfunc()
  File "/home/ubuntu/.local/lib/python3.9/site-packages/django/contrib/auth/middleware.py", line 23, in <lambda>
    request.user = SimpleLazyObject(lambda: get_user(request))
  File "/home/ubuntu/.local/lib/python3.9/site-packages/django/contrib/auth/middleware.py", line 11, in get_user
    request._cached_user = auth.get_user(request)
  File "/home/ubuntu/.local/lib/python3.9/site-packages/django/contrib/auth/__init__.py", line 177, in get_user
    user_id = _get_user_session_key(request)
  File "/home/ubuntu/.local/lib/python3.9/site-packages/django/contrib/auth/__init__.py", line 60, in _get_user_session_key
    return get_user_model()._meta.pk.to_python(request.session[SESSION_KEY])
  File "/home/ubuntu/.local/lib/python3.9/site-packages/django/contrib/sessions/backends/base.py", line 65, in __getitem__
    return self._session[key]
  File "/home/ubuntu/.local/lib/python3.9/site-packages/django/contrib/sessions/backends/base.py", line 238, in _get_session
    self._session_cache = self.load()
  File "/home/ubuntu/.local/lib/python3.9/site-packages/django/contrib/sessions/backends/db.py", line 43, in load
    s = self._get_session_from_db()
  File "/home/ubuntu/.local/lib/python3.9/site-packages/django/contrib/sessions/backends/db.py", line 32, in _get_session_from_db
    return self.model.objects.get(
  File "/home/ubuntu/.local/lib/python3.9/site-packages/django/db/models/manager.py", line 85, in manager_method
    return getattr(self.get_queryset(), name)(*args, **kwargs)
  File "/home/ubuntu/.local/lib/python3.9/site-packages/django/db/models/query.py", line 431, in get
    num = len(clone)
  File "/home/ubuntu/.local/lib/python3.9/site-packages/django/db/models/query.py", line 262, in __len__
    self._fetch_all()
  File "/home/ubuntu/.local/lib/python3.9/site-packages/django/db/models/query.py", line 1324, in _fetch_all
    self._result_cache = list(self._iterable_class(self))
  File "/home/ubuntu/.local/lib/python3.9/site-packages/django/db/models/query.py", line 51, in __iter__
    results = compiler.execute_sql(chunked_fetch=self.chunked_fetch, chunk_size=self.chunk_size)
  File "/home/ubuntu/.local/lib/python3.9/site-packages/django/db/models/sql/compiler.py", line 1173, in execute_sql
    cursor = self.connection.cursor()
  File "/home/ubuntu/.local/lib/python3.9/site-packages/django/utils/asyncio.py", line 26, in inner
    return func(*args, **kwargs)
  File "/home/ubuntu/.local/lib/python3.9/site-packages/django/db/backends/base/base.py", line 259, in cursor
    return self._cursor()
  File "/home/ubuntu/.local/lib/python3.9/site-packages/django/db/backends/base/base.py", line 235, in _cursor
    self.ensure_connection()
  File "/home/ubuntu/.local/lib/python3.9/site-packages/django/utils/asyncio.py", line 26, in inner
    return func(*args, **kwargs)
  File "/home/ubuntu/.local/lib/python3.9/site-packages/django/db/backends/base/base.py", line 219, in ensure_connection
    self.connect()
  File "/home/ubuntu/.local/lib/python3.9/site-packages/django/db/utils.py", line 90, in __exit__
    raise dj_exc_value.with_traceback(traceback) from exc_value
  File "/home/ubuntu/.local/lib/python3.9/site-packages/django/db/backends/base/base.py", line 219, in ensure_connection
    self.connect()
  File "/home/ubuntu/.local/lib/python3.9/site-packages/django/utils/asyncio.py", line 26, in inner
    return func(*args, **kwargs)
  File "/home/ubuntu/.local/lib/python3.9/site-packages/django/db/backends/base/base.py", line 200, in connect
    self.connection = self.get_new_connection(conn_params)
  File "/home/ubuntu/.local/lib/python3.9/site-packages/django/utils/asyncio.py", line 26, in inner
    return func(*args, **kwargs)
  File "/home/ubuntu/.local/lib/python3.9/site-packages/django/db/backends/mysql/base.py", line 234, in get_new_connection
    connection = Database.connect(**conn_params)
  File "/home/ubuntu/.local/lib/python3.9/site-packages/MySQLdb/__init__.py", line 130, in Connect
    return Connection(*args, **kwargs)
  File "/home/ubuntu/.local/lib/python3.9/site-packages/MySQLdb/connections.py", line 185, in __init__
    super().__init__(*args, **kwargs2)
django.db.utils.OperationalError: (2002, "Can't connect to local MySQL server through socket '/var/run/mysqld/mysqld.sock' (2)")
2021-05-09 15:58:46,516 | [ERROR] | Internal Server Error: /admin/
Traceback (most recent call last):
  File "/home/ubuntu/.local/lib/python3.9/site-packages/django/contrib/sessions/backends/base.py", line 233, in _get_session
    return self._session_cache
AttributeError: 'SessionStore' object has no attribute '_session_cache'

During handling of the above exception, another exception occurred:

Traceback (most recent call last):
  File "/home/ubuntu/.local/lib/python3.9/site-packages/django/db/backends/base/base.py", line 219, in ensure_connection
    self.connect()
  File "/home/ubuntu/.local/lib/python3.9/site-packages/django/utils/asyncio.py", line 26, in inner
    return func(*args, **kwargs)
  File "/home/ubuntu/.local/lib/python3.9/site-packages/django/db/backends/base/base.py", line 200, in connect
    self.connection = self.get_new_connection(conn_params)
  File "/home/ubuntu/.local/lib/python3.9/site-packages/django/utils/asyncio.py", line 26, in inner
    return func(*args, **kwargs)
  File "/home/ubuntu/.local/lib/python3.9/site-packages/django/db/backends/mysql/base.py", line 234, in get_new_connection
    connection = Database.connect(**conn_params)
  File "/home/ubuntu/.local/lib/python3.9/site-packages/MySQLdb/__init__.py", line 130, in Connect
    return Connection(*args, **kwargs)
  File "/home/ubuntu/.local/lib/python3.9/site-packages/MySQLdb/connections.py", line 185, in __init__
    super().__init__(*args, **kwargs2)
MySQLdb._exceptions.OperationalError: (2002, "Can't connect to local MySQL server through socket '/var/run/mysqld/mysqld.sock' (2)")

The above exception was the direct cause of the following exception:

Traceback (most recent call last):
  File "/home/ubuntu/.local/lib/python3.9/site-packages/django/core/handlers/exception.py", line 47, in inner
    response = get_response(request)
  File "/home/ubuntu/.local/lib/python3.9/site-packages/django/core/handlers/base.py", line 181, in _get_response
    response = wrapped_callback(request, *callback_args, **callback_kwargs)
  File "/home/ubuntu/.local/lib/python3.9/site-packages/django/contrib/admin/sites.py", line 250, in wrapper
    return self.admin_view(view, cacheable)(*args, **kwargs)
  File "/home/ubuntu/.local/lib/python3.9/site-packages/django/utils/decorators.py", line 130, in _wrapped_view
    response = view_func(request, *args, **kwargs)
  File "/home/ubuntu/.local/lib/python3.9/site-packages/django/views/decorators/cache.py", line 44, in _wrapped_view_func
    response = view_func(request, *args, **kwargs)
  File "/home/ubuntu/.local/lib/python3.9/site-packages/django/contrib/admin/sites.py", line 221, in inner
    if not self.has_permission(request):
  File "/home/ubuntu/.local/lib/python3.9/site-packages/django/contrib/admin/sites.py", line 195, in has_permission
    return request.user.is_active and request.user.is_staff
  File "/home/ubuntu/.local/lib/python3.9/site-packages/django/utils/functional.py", line 246, in inner
    self._setup()
  File "/home/ubuntu/.local/lib/python3.9/site-packages/django/utils/functional.py", line 382, in _setup
    self._wrapped = self._setupfunc()
  File "/home/ubuntu/.local/lib/python3.9/site-packages/django/contrib/auth/middleware.py", line 23, in <lambda>
    request.user = SimpleLazyObject(lambda: get_user(request))
  File "/home/ubuntu/.local/lib/python3.9/site-packages/django/contrib/auth/middleware.py", line 11, in get_user
    request._cached_user = auth.get_user(request)
  File "/home/ubuntu/.local/lib/python3.9/site-packages/django/contrib/auth/__init__.py", line 177, in get_user
    user_id = _get_user_session_key(request)
  File "/home/ubuntu/.local/lib/python3.9/site-packages/django/contrib/auth/__init__.py", line 60, in _get_user_session_key
    return get_user_model()._meta.pk.to_python(request.session[SESSION_KEY])
  File "/home/ubuntu/.local/lib/python3.9/site-packages/django/contrib/sessions/backends/base.py", line 65, in __getitem__
    return self._session[key]
  File "/home/ubuntu/.local/lib/python3.9/site-packages/django/contrib/sessions/backends/base.py", line 238, in _get_session
    self._session_cache = self.load()
  File "/home/ubuntu/.local/lib/python3.9/site-packages/django/contrib/sessions/backends/db.py", line 43, in load
    s = self._get_session_from_db()
  File "/home/ubuntu/.local/lib/python3.9/site-packages/django/contrib/sessions/backends/db.py", line 32, in _get_session_from_db
    return self.model.objects.get(
  File "/home/ubuntu/.local/lib/python3.9/site-packages/django/db/models/manager.py", line 85, in manager_method
    return getattr(self.get_queryset(), name)(*args, **kwargs)
  File "/home/ubuntu/.local/lib/python3.9/site-packages/django/db/models/query.py", line 431, in get
    num = len(clone)
  File "/home/ubuntu/.local/lib/python3.9/site-packages/django/db/models/query.py", line 262, in __len__
    self._fetch_all()
  File "/home/ubuntu/.local/lib/python3.9/site-packages/django/db/models/query.py", line 1324, in _fetch_all
    self._result_cache = list(self._iterable_class(self))
  File "/home/ubuntu/.local/lib/python3.9/site-packages/django/db/models/query.py", line 51, in __iter__
    results = compiler.execute_sql(chunked_fetch=self.chunked_fetch, chunk_size=self.chunk_size)
  File "/home/ubuntu/.local/lib/python3.9/site-packages/django/db/models/sql/compiler.py", line 1173, in execute_sql
    cursor = self.connection.cursor()
  File "/home/ubuntu/.local/lib/python3.9/site-packages/django/utils/asyncio.py", line 26, in inner
    return func(*args, **kwargs)
  File "/home/ubuntu/.local/lib/python3.9/site-packages/django/db/backends/base/base.py", line 259, in cursor
    return self._cursor()
  File "/home/ubuntu/.local/lib/python3.9/site-packages/django/db/backends/base/base.py", line 235, in _cursor
    self.ensure_connection()
  File "/home/ubuntu/.local/lib/python3.9/site-packages/django/utils/asyncio.py", line 26, in inner
    return func(*args, **kwargs)
  File "/home/ubuntu/.local/lib/python3.9/site-packages/django/db/backends/base/base.py", line 219, in ensure_connection
    self.connect()
  File "/home/ubuntu/.local/lib/python3.9/site-packages/django/db/utils.py", line 90, in __exit__
    raise dj_exc_value.with_traceback(traceback) from exc_value
  File "/home/ubuntu/.local/lib/python3.9/site-packages/django/db/backends/base/base.py", line 219, in ensure_connection
    self.connect()
  File "/home/ubuntu/.local/lib/python3.9/site-packages/django/utils/asyncio.py", line 26, in inner
    return func(*args, **kwargs)
  File "/home/ubuntu/.local/lib/python3.9/site-packages/django/db/backends/base/base.py", line 200, in connect
    self.connection = self.get_new_connection(conn_params)
  File "/home/ubuntu/.local/lib/python3.9/site-packages/django/utils/asyncio.py", line 26, in inner
    return func(*args, **kwargs)
  File "/home/ubuntu/.local/lib/python3.9/site-packages/django/db/backends/mysql/base.py", line 234, in get_new_connection
    connection = Database.connect(**conn_params)
  File "/home/ubuntu/.local/lib/python3.9/site-packages/MySQLdb/__init__.py", line 130, in Connect
    return Connection(*args, **kwargs)
  File "/home/ubuntu/.local/lib/python3.9/site-packages/MySQLdb/connections.py", line 185, in __init__
    super().__init__(*args, **kwargs2)
django.db.utils.OperationalError: (2002, "Can't connect to local MySQL server through socket '/var/run/mysqld/mysqld.sock' (2)")
2021-05-09 15:58:46,683 | [WARNING] | Not Found: /favicon.ico
2021-05-09 16:04:00,251 | [WARNING] | Not Found: /favicon.ico
2021-05-09 16:04:01,422 | [WARNING] | Not Found: /favicon.ico
2021-05-09 16:04:01,784 | [WARNING] | Not Found: /favicon.ico
